Workbook

Sheet Bond Analytics
A1: Bond Ticker | B1: CUSIP | C1: Company Name | D1: Rating | E1: Rating2 | F1: Amount Issued $M | G1: Amount Outstanding $M | H1: Issue Date | I1: Date of Maturity | J1: Embedded Option | K1: Next Call Date | L1: Call Price(Par) | M1: Number of periods to call | N1: YTC | O1: Source | P1: Coupon | Q1: Coupon Frequency | R1: Closing Price of Bond | S1: Settlement Date | T1: Years to Maturity | U1: FV | V1: Coupon Pmt | W1: N | X1: I/Y | Y1: PV | Z1: t | AA1: Next Coupon Date | AB1: First Coupon Date | AC1: Recent Coupon Payment | AD1: Coupon Months | AE1: Flat Price | AF1: Accrued Interest | AG1: Full Price | AH1: Annual YTM | AI1: Modified Duration | AJ1: Convexity | AK1: Price if YTM+100 | AL1: Price if YTM-100
D2: Moody's | E2: S&P
A3: Johnson & Johnson 2,95% 17/27 | B3: US478160CE22 | C3: Johnson & Johnson | D3: Aaa | E3: AAA | F3: 1000 | G3: 1000 | H3: 42797 | I3: 46449 | J3: Call | K3: 45671 | L3: 100 | M3: NA | N3: NA | O3: https://www.boerse-frankfurt.de/bond/us478160ce22-johnson-johnson-2-95-17-27 | P3: 0.0295 | Q3: 2 | R3: 98.07 | S3: 45772 | T3: =YEARFRAC(S3,I3) -> 1.8555556 | U3: 100 | V3: =U3*P3/2 -> 1.475 | W3: =T3*Q3 -> 3.7111111 | X3: =AH3/2 -> 0.020191646 | Y3: =PV($X$3,$W$3,-$V$3,-$U$3) -> 98.073024 | Z3: =(S3-AC3)/(AA3-AC3) -> 0.25543478 | AA3: 45909 | AB3: 42803 | AC3: 45725 | AD3: March/September | AE3: =PV($X$3,$W$3,-$V$3,-$U$3) -> 98.073024 | AF3: =V3*Z3 -> 0.3767663 | AG3: =AE3+AF3 -> 98.449791 | AH3: =YIELD(S3,I3,P3,R3,U3,2) -> 0.040383292 | AI3: ='Working Sheet'!C11 -> 3.8348273 | AJ3: ='Working Sheet'!C14 -> 18.654969 | AK3: =PV(B17,$W$3,-$V$3,-$U$3) -> 94.651899 | AL3: =PV(C17,W3,-V3,-U3) -> 101.64876
A4: Pfizer Inc. 1.75% 21/31 | B4: US717081FB45 | C4: Pfizer Inc. | D4: A2 | E4: A | F4: 1000 | G4: 1000 | H4: 44426 | I4: 48078 | J4: Call | K4: 47102 | L4: 100 | M4: =YEARFRAC(S4,K4)*2 -> 7.2777778 | N4: =RATE(7,-V4,-R4,U4)*2 -> 0.028615609 | O4: https://www.boerse-frankfurt.de/bond/us717081fb45-pfizer-inc-1-75-21-31 | P4: 0.0175 | Q4: 2 | R4: 84.745 | S4: 45772 | T4: =YEARFRAC(S4,I4) -> 6.3138889 | U4: 100 | V4: =U4*P4/2 -> 0.875 | W4: =T4*Q4 -> 12.627778 | X4: =AH4/2 -> 0.022785794 | Y4: =PV($X$4,$W$4,-$V$4,-$U$4) -> 84.747301 | Z4: =(S4-AC4)/(AA4-AC4) -> 0.36464088 | AA4: 45887 | AB4: 44610 | AC4: 45706 | AD4: February/August | AE4: =PV($X$4,$W$4,-$V$4,-$U$4) -> 84.747301 | AF4: =V4*Z4 -> 0.31906077 | AG4: =AE4+AF4 -> 85.066362 | AH4: =YIELD(S4,I4,P4,R4,U4,2) -> 0.045571589 | AI4: ='Working Sheet'!L19 -> 11.992945 | AJ4: ='Working Sheet'!L22 -> 13.126808 | AK4: =PV(B18,W4,-V4,-U4) -> 75.45746 | AL4: =PV(C18,W4,-V4,-U4) -> 95.3053
A5: JPMorgan Chase & Co. 4.26% 17/48 | B5: US46647PAA49 | C5: JPMorgan Chase & Co. | D5: A1 | E5: A | F5: 2000 | G5: 2000 | H5: 42788 | I5: 54110 | J5: Call | K5: 46590 | L5: 100 | M5: =YEARFRAC(S5,K5)*2 -> 4.4833333 | N5: =RATE(7,-V5,-R5,U5)*2 -> 0.011968864 | O5: https://www.boerse-frankfurt.de/bond/us46647paa49-jpmorgan-chase-co-4-26-17-48 | P5: 0.0426 | Q5: 2 | R5: 81.35 | S5: 45772 | T5: =YEARFRAC(S5,I5) -> 22.825 | U5: 100 | V5: =U5*P5/2 -> 2.13 | W5: =T5*Q5 -> 45.65 | X5: =AH5/2 -> 0.02867474 | Y5: =PV($X$5,$W$5,-$V$5,-$U$5) -> 81.35684 | Z5: =(S5-AC5)/(AA5-AC5) -> 0.34254144 | AA5: 45891 | AB5: 42969 | AC5: 45710 | AD5: August/February | AE5: =PV($X$5,$W$5,-$V$5,-$U$5) -> 81.35684 | AF5: =V5*Z5 -> 0.72961326 | AG5: =AE5+AF5 -> 82.086453 | AH5: =YIELD(S5,I5,P5,R5,U5,2) -> 0.05734948 | AI5: ='Working Sheet'!T52 -> 27.034129 | AJ5: ='Working Sheet'!T55 -> 36.554434 | AK5: =PV(B19,W5,-V5,-U5) -> 63.135484 | AL5: =PV(C19,W5,-V5,-U5) -> 108.25744
A6: General Motors Financial Co. Inc. 6.1% 23/34 | B6: US37045XEP78 | C6: General Motors Financial Co. | D6: Baa2 | E6: BBB | F6: 1500 | G6: 1500 | H6: 45119 | I6: 49126 | J6: Call | K6: 45920 | L6: 100 | M6: =YEARFRAC(S6,K6)*2 -> 0.80555556 | N6: =RATE(7,-V6,-R6,U6)*2 -> -0.060949607 | O6: https://www.boerse-frankfurt.de/bond/us37045xep78-general-motors-financial-co-inc-6-1-23-34 | P6: 0.061 | Q6: 2 | R6: 99.98 | S6: 45772 | T6: =YEARFRAC(S6,I6) -> 9.1833333 | U6: 100 | V6: =U6*P6/2 -> 3.05 | W6: =T6*Q6 -> 18.366667 | X6: =AH6/2 -> 0.03050672 | Y6: =PV($X$6,$W$6,-$V$6,-$U$6) -> 99.990656 | Z6: =(S6-AC6)/(AA6-AC6) -> 0.59668508 | AA6: 45845 | AB6: 45480 | AC6: 45664 | AD6: January/July | AE6: =PV($X$6,$W$6,-$V$6,-$U$6) -> 99.990656 | AF6: =V6*Z6 -> 1.8198895 | AG6: =AE6+AF6 -> 101.81055 | AH6: =YIELD(S6,I6,P6,R6,U6,2) -> 0.061013441 | AI6: ='Working Sheet'!AB25 -> 13.695553 | AJ6: ='Working Sheet'!AB28 -> 16.37629 | AK6: =PV(B20,W6,-V6,-U6) -> 87.217369 | AL6: =PV(C20,W6,-V6,-U6) -> 115.1773
A9: Assumptions
A10: All calculations are based on Actual, Actual Day count
A11: All calculations are done based on FV=100
A12: Rounded Off assuming if there is partial period bond still pays full coupan for it.
A13: All bonds are callable at par value=100
A14: Not able to calculate YTC as bond is already called off
A16: Bonds | B16: YTM+100 | C16: YTM-100
A17: JNJ | B17: 0.0302 | C17: 0.0102
A18: PFE | B18: 0.0328 | C18: 0.0128
A19: JPM | B19: 0.0386 | C19: 0.0186
A20: GMF | B20: 0.0405 | C20: 0.0205

Sheet Bond Portfolio
A1: Bond | B1: Face Value (FV) | C1: Flat Price (Market Price) | D1: Coupon % | E1: YTM % | F1: Modified Duration (years) | G1: Convexity (years^2) | H1: Weight | I1: Allocation $ | J1: Coupon Payment | K1: Weighted Coupon Contribution | L1: Weighted YTM Contribution | M1: Weighted Duration Contribution | N1: Weighted Convexity Contribution
A2: JNJ | B2: 100 | C2: 98.07 | D2: 2.95 | E2: 4.04 | F2: 3.835 | G2: 4.66 | H2: 0.4 | I2: 400000 | J2: 2.95 | K2: =J2*H2 -> 1.18 | L2: =E2*H2 -> 1.616 | M2: =F2*H2 -> 1.534 | N2: =G2*H2 -> 1.864
A3: PFE | B3: 100 | C3: 84.745 | D3: 1.75 | E3: 4.56 | F3: 11.993 | G3: 3.28 | H3: 0.2 | I3: 200000 | J3: 1.75 | K3: =J3*H3 -> 0.35 | L3: =E3*H3 -> 0.912 | M3: =F3*H3 -> 2.3986 | N3: =G3*H3 -> 0.656
A4: JPM | B4: 100 | C4: 81.35 | D4: 4.26 | E4: 5.73 | F4: 13.696 | G4: 4.09 | H4: 0.25 | I4: 250000 | J4: 4.26 | K4: =J4*H4 -> 1.065 | L4: =E4*H4 -> 1.4325 | M4: =F4*H4 -> 3.424 | N4: =G4*H4 -> 1.0225
A5: GMF | B5: 100 | C5: 99.98 | D5: 6.1 | E5: 6.1 | F5: 27.034 | G5: 9.14 | H5: 0.15 | I5: 150000 | J5: 6.1 | K5: =J5*H5 -> 0.915 | L5: =E5*H5 -> 0.915 | M5: =F5*H5 -> 4.0551 | N5: =G5*H5 -> 1.371
F8: Explain Allocation Strategy
A9: Metric | B9: Value | F9: The portfolio allocation was designed to balance yield and risk across different credit ratings and industries. Higher weightings were given to stable investment-grade bonds like JNJ and JPM to anchor the portfolio with lower volatility, while bonds like GMF with higher yields and longer durations provided additional return potential. This allocation ensures diversification while maintaining a moderate risk profile.
A10: Portfolio Average Coupon (%) | B10: =K2+K3+K4+K5 -> 3.51
A11: Portfolio YTM (%) | B11: =L2+L3+L4+L5 -> 4.8755
A12: Portfolio Modified Duration (years) | B12: =M2+M3+M4+M5 -> 11.4117
A13: Portfolio Convexity (years^2) | B13: =N2+N3+N4+N5 -> 4.9135
A16: Scenario | B16: Using Duration Only | C16: Using Duration+Convexity
A17: Change in Portfolio if 100bps shift upwards | B17: =-(B12)*0.01 -> -0.114117 | C17: =(-B12*0.01)+(0.5*B13*(0.01^2)) -> -0.11387132
A18: Change in Portfolio if 100bps shift Downwords | B18: =(B12)*0.01 -> 0.114117 | C18: =(B12*0.01)+(0.5*B13*(0.01^2)) -> 0.11436267 | F18: Explain Sensitivity Results
F19: The portfolio shows moderate sensitivity to interest rate changes, with an estimated 11.42% decrease in value if rates increase by 100 basis points and an 11.44% increase if rates decrease by the same amount. Including convexity in the analysis slightly reduces the estimated impact, as convexity accounts for the non-linear relationship between bond prices and yields. This highlights the portfolio’s balanced exposure to duration risk and its ability to cushion against extreme rate movements.

Sheet Raw data
A1: Bond | B1: Coupan Interest rate | C1: Frequency
A2: Johnson & Johnson 2,95% 17/27 | B2: 2.95 | C2: 2
A3: Pfizer Inc. 1.75% 21/31 | B3: 1.75 | C3: 2
A4: JPMorgan Chase & Co. 4.26% 17/48 | B4: 4.26 | C4: 2
A5: General Motors Financial Co. Inc. 6.1% 23/34 | B5: 6.1 | C5: 2
F27: Bond Ticker | G27: CUSIP | H27: Company Name | I27: Settlement Date | J27: Years to Maturity | K27: FV | L27: Coupon Pmt | M27: N | N27: I/Y | O27: PV | P27: t | Q27: First Coupon Date | R27: Recent Coupon Payment | S27: Coupon Months
F28: DKS 4.1 01/15/52 | G28: 253393AG7 | H28: Dick's Sporting Goods | I28: 45402 | J28: 28.14 | K28: 100 | L28: 2.05 | M28: 56 | N28: 0.0287 | O28: -77.32 | P28: 98 | Q28: 44755 | R28: 45304 | S28: Jul | T28: Jan
F29: F 3 1/4 02/12/2032 | G29: 345370DA5 | H29: Ford Motor Company | I29: 45402 | J29: 7.73 | K29: 100 | L29: 1.63 | M29: 16 | N29: 0.0197 | O29: -95.37 | P29: 132 | Q29: 44722 | R29: 45270 | S29: June | T29: Dec
F30: AAPL 1.8 09/11/24 | G30: 037833DM9 | H30: Apple Inc | I30: 45402 | J30: 0.56 | K30: 100 | L30: 0.9 | M30: 2 | N30: 0.0091 | O30: -99.97 | P30: 164 | Q30: 43959 | R30: 45238 | S30: May | T30: Nov
F31: CAT 1.7 01/08/27 | G31: 14913R2U0 | H31: Caterpillar Finl Service | I31: 45402 | J31: 2.76 | K31: 100 | L31: 0.85 | M31: 6 | N31: 0.0092 | O31: -99.57 | P31: 102 | Q31: 44751 | R31: 45300 | S31: July | T31: Jan
F32: BK 2 1/2 01/26/32 | G32: 06406RBB2 | H32: Bank of NY Mellon Corp | I32: 45402 | J32: 7.88 | K32: 100 | L32: 1.25 | M32: 16 | N32: 0.0149 | O32: -96.59 | P32: 86 | Q32: 44767 | R32: 45316 | S32: July | T32: Jan
F33: DELL 6.2 07/15/30 | G33: 24703TAH9 | H33: Dell International LLC | I33: 45402 | J33: 6.33 | K33: 100 | L33: 3.1 | M33: 13 | N33: 0.0296 | O33: -101.53 | P33: 97 | Q33: 44575 | R33: 45305 | S33: July | T33: Jan
F38: Bond Ticker | G38: CUSIP | H38: Company Name | I38: Rating | J38: Amount Issued $M | K38: Amount Outstanding $M | L38: Issue Date | M38: Date of Maturity | N38: Embeded Option | O38: Call Date | P38: Call Price | Q38: Coupon | R38: Coupon Freq | S38: Annual YTM
F39: DKS 4.1 01/15/52 | G39: 253393AG7 | H39: Dick's Sporting Goods | I39: BBB - | J39: 750 | K39: 750 | L39: 44575 | M39: 55533 | N39: Call | O39: 55349 | P39: 100 | Q39: 0.041 | R39: SA | S39: 0.05736
F40: F 3 1/4 02/12/2032 | G40: 345370DA5 | H40: Ford Motor Company | I40: BB+ | J40: 2500 | K40: 2500 | L40: 44512 | M40: 48184 | N40: Call | O40: 48164 | P40: 100 | Q40: 0.0325 | R40: SA | S40: 0.03932
F41: AAPL 1.8 09/11/24 | G41: 037833DM9 | H41: Apple Inc | I41: AA+ | J41: 750 | K41: 750 | L41: 43719 | M41: 45605 | N41: Call | O41: 45515 | P41: 100 | Q41: 0.018 | R41: SA | S41: 0.01827
F42: CAT 1.7 01/08/27 | G42: 14913R2U0 | H42: Caterpillar Finl Service | I42: A | J42: 500 | K42: 500 | L42: 44571 | M42: 46395 | N42: No | Q42: 0.017 | R42: SA | S42: 0.01847
F43: BK 2 1/2 01/26/32 | G43: 06406RBB2 | H43: Bank of NY Mellon Corp | I43: A+ | J43: 450 | K43: 450 | L43: 44587 | M43: 48239 | N43: Call | O43: 48147 | P43: 100 | Q43: 0.025 | R43: SA | S43: 0.02982
F44: DELL 6.2 07/15/30 | G44: 24703TAH9 | H44: Dell International LLC | I44: BBB | J44: 749 | K44: 749 | L44: 44392 | M44: 47679 | N44: Call | O44: 47588 | P44: 100 | Q44: 0.062 | R44: SA | S44: 0.05913

Sheet Working Sheet
A2: Bond | B2: Period (t) | C2: Cash Flow | D2: Discount Factor | E2: PV of Cash Flow | F2: t × PV | G2: t(t+1) × PV | I2: Bond | J2: Period (t) | K2: Cash Flow | L2: Discount Factor | M2: PV of Cash Flow | N2: t × PV | O2: t(t+1) × PV | Q2: Bond | R2: Period (t) | S2: Cash Flow | T2: Discount Factor | U2: PV of Cash Flow | V2: t × PV | W2: t(t+1) × PV | Y2: Bond | Z2: Period (t) | AA2: Cash Flow | AB2: Discount Factor | AC2: PV of Cash Flow | AD2: t × PV | AE2: t(t+1) × PV
A3: JNJ | B3: 1 | C3: 1.48 | D3: =1/1.0202 -> 0.98019996 | E3: =C3*D3 -> 1.4506959 | F3: =E3*B3 -> 1.4506959 | G3: =B3*(B3+1)*E3 -> 2.9013919 | I3: PFE | J3: 1 | K3: 0.88 | L3: =1/1.0228 -> 0.97770825 | M3: =K3*L3 -> 0.86038326 | N3: =J3*M3 -> 0.86038326 | O3: =J3*(J3+1)*M3 -> 1.7207665 | Q3: JPM | R3: 1 | S3: 2.13 | T3: =1/1.0287 -> 0.97210071 | U3: =S3*T3 -> 2.0705745 | V3: =R3*U3 -> 2.0705745 | W3: =R3*(R3+1)*U3 -> 4.141149 | Y3: GMF | Z3: 1 | AA3: 3.05 | AB3: =1/1.0305 -> 0.97040272 | AC3: =AA3*AB3 -> 2.9597283 | AD3: =Z3*AC3 -> 2.9597283 | AE3: =Z3*(Z3+1)*AC3 -> 5.9194566
A4: JNJ | B4: 2 | C4: 1.48 | D4: =D3/1.0202 -> 0.96079196 | E4: =C4*D4 -> 1.4219721 | F4: =E4*B4 -> 2.8439442 | G4: =B4*(B4+1)*E4 -> 8.5318326 | I4: PFE | J4: 2 | K4: 0.88 | L4: =L3/1.0228 -> 0.95591343 | M4: =K4*L4 -> 0.84120381 | N4: =J4*M4 -> 1.6824076 | O4: =J4*(J4+1)*M4 -> 5.0472229 | Q4: JPM | R4: 2 | S4: 2.13 | T4: =T3/1.0287 -> 0.94497979 | U4: =S4*T4 -> 2.012807 | V4: =R4*U4 -> 4.0256139 | W4: =R4*(R4+1)*U4 -> 12.076842 | Y4: GMF | Z4: 2 | AA4: 3.05 | AB4: =AB3/1.0305 -> 0.94168143 | AC4: =AA4*AB4 -> 2.8721284 | AD4: =Z4*AC4 -> 5.7442567 | AE4: =Z4*(Z4+1)*AC4 -> 17.23277
A5: JNJ | B5: 3 | C5: 1.48 | D5: =D4/1.0202 -> 0.94176824 | E5: =C5*D5 -> 1.393817 | F5: =E5*B5 -> 4.181451 | G5: =B5*(B5+1)*E5 -> 16.725804 | I5: PFE | J5: 3 | K5: 0.88 | L5: =L4/1.0228 -> 0.93460444 | M5: =K5*L5 -> 0.82245191 | N5: =J5*M5 -> 2.4673557 | O5: =J5*(J5+1)*M5 -> 9.8694229 | Q5: JPM | R5: 3 | S5: 2.13 | T5: =T4/1.0287 -> 0.91861552 | U5: =S5*T5 -> 1.9566511 | V5: =R5*U5 -> 5.8699532 | W5: =R5*(R5+1)*U5 -> 23.479813 | Y5: GMF | Z5: 3 | AA5: 3.05 | AB5: =AB4/1.0305 -> 0.91381022 | AC5: =AA5*AB5 -> 2.7871212 | AD5: =Z5*AC5 -> 8.3613635 | AE5: =Z5*(Z5+1)*AC5 -> 33.445454
A6: JNJ | B6: 4 | C6: 101.47 | D6: =D5/1.0202 -> 0.9231212 | E6: =C6*D6 -> 93.669108 | F6: =E6*B6 -> 374.67643 | G6: =B6*(B6+1)*E6 -> 1873.3822 | I6: PFE | J6: 4 | K6: 0.88 | L6: =L5/1.0228 -> 0.91377048 | M6: =K6*L6 -> 0.80411802 | N6: =J6*M6 -> 3.2164721 | O6: =J6*(J6+1)*M6 -> 16.08236 | Q6: JPM | R6: 4 | S6: 2.13 | T6: =T5/1.0287 -> 0.8929868 | U6: =S6*T6 -> 1.9020619 | V6: =R6*U6 -> 7.6082476 | W6: =R6*(R6+1)*U6 -> 38.041238 | Y6: GMF | Z6: 4 | AA6: 3.05 | AB6: =AB5/1.0305 -> 0.88676392 | AC6: =AA6*AB6 -> 2.70463 | AD6: =Z6*AC6 -> 10.81852 | AE6: =Z6*(Z6+1)*AC6 -> 54.092599
D7: Sum | E7: =SUM(E3:E6) -> 97.935593 | F7: =SUM(F3:F6) -> 383.15252 | G7: =SUM(G3:G6) -> 1901.5412 | I7: PFE | J7: 5 | K7: 0.88 | L7: =L6/1.0228 -> 0.89340094 | M7: =K7*L7 -> 0.78619282 | N7: =J7*M7 -> 3.9309641 | O7: =J7*(J7+1)*M7 -> 23.585785 | Q7: JPM | R7: 5 | S7: 2.13 | T7: =T6/1.0287 -> 0.8680731 | U7: =S7*T7 -> 1.8489957 | V7: =R7*U7 -> 9.2449786 | W7: =R7*(R7+1)*U7 -> 55.469871 | Y7: GMF | Z7: 5 | AA7: 3.05 | AB7: =AB6/1.0305 -> 0.86051812 | AC7: =AA7*AB7 -> 2.6245803 | AD7: =Z7*AC7 -> 13.122901 | AE7: =Z7*(Z7+1)*AC7 -> 78.737408
I8: PFE | J8: 6 | K8: 0.88 | L8: =L7/1.0228 -> 0.87348547 | M8: =K8*L8 -> 0.76866721 | N8: =J8*M8 -> 4.6120033 | O8: =J8*(J8+1)*M8 -> 32.284023 | Q8: JPM | R8: 6 | S8: 2.13 | T8: =T7/1.0287 -> 0.84385448 | U8: =S8*T8 -> 1.79741 | V8: =R8*U8 -> 10.78446 | W8: =R8*(R8+1)*U8 -> 75.491222 | Y8: GMF | Z8: 6 | AA8: 3.05 | AB8: =AB7/1.0305 -> 0.83504912 | AC8: =AA8*AB8 -> 2.5468998 | AD8: =Z8*AC8 -> 15.281399 | AE8: =Z8*(Z8+1)*AC8 -> 106.96979
I9: PFE | J9: 7 | K9: 0.88 | L9: =L8/1.0228 -> 0.85401395 | M9: =K9*L9 -> 0.75153228 | N9: =J9*M9 -> 5.2607259 | O9: =J9*(J9+1)*M9 -> 42.085807 | Q9: JPM | R9: 7 | S9: 2.13 | T9: =T8/1.0287 -> 0.82031154 | U9: =S9*T9 -> 1.7472636 | V9: =R9*U9 -> 12.230845 | W9: =R9*(R9+1)*U9 -> 97.84676 | Y9: GMF | Z9: 7 | AA9: 3.05 | AB9: =AB8/1.0305 -> 0.81033394 | AC9: =AA9*AB9 -> 2.4715185 | AD9: =Z9*AC9 -> 17.30063 | AE9: =Z9*(Z9+1)*AC9 -> 138.40504
B10: D_Mac | C10: =F7/E7 -> 3.9122908 | I10: PFE | J10: 8 | K10: 0.88 | L10: =L9/1.0228 -> 0.83497649 | M10: =K10*L10 -> 0.73477931 | N10: =J10*M10 -> 5.8782345 | O10: =J10*(J10+1)*M10 -> 52.90411 | Q10: JPM | R10: 8 | S10: 2.13 | T10: =T9/1.0287 -> 0.79742543 | U10: =S10*T10 -> 1.6985162 | V10: =R10*U10 -> 13.588129 | W10: =R10*(R10+1)*U10 -> 122.29316 | Y10: GMF | Z10: 8 | AA10: 3.05 | AB10: =AB9/1.0305 -> 0.78635025 | AC10: =AA10*AB10 -> 2.3983683 | AD10: =Z10*AC10 -> 19.186946 | AE10: =Z10*(Z10+1)*AC10 -> 172.68252
B11: D_Mod | C11: =C10/C12 -> 3.8348273 | I11: PFE | J11: 9 | K11: 0.88 | L11: =L10/1.0228 -> 0.8163634 | M11: =K11*L11 -> 0.71839979 | N11: =J11*M11 -> 6.4655981 | O11: =J11*(J11+1)*M11 -> 64.655981 | Q11: JPM | R11: 9 | S11: 2.13 | T11: =T10/1.0287 -> 0.77517783 | U11: =S11*T11 -> 1.6511288 | V11: =R11*U11 -> 14.860159 | W11: =R11*(R11+1)*U11 -> 148.60159 | Y11: GMF | Z11: 9 | AA11: 3.05 | AB11: =AB10/1.0305 -> 0.76307642 | AC11: =AA11*AB11 -> 2.3273831 | AD11: =Z11*AC11 -> 20.946448 | AE11: =Z11*(Z11+1)*AC11 -> 209.46448
B12: 1+I/Y | C12: 1.0202 | I12: PFE | J12: 10 | K12: 0.88 | L12: =L11/1.0228 -> 0.79816523 | M12: =K12*L12 -> 0.7023854 | N12: =J12*M12 -> 7.023854 | O12: =J12*(J12+1)*M12 -> 77.262395 | Q12: JPM | R12: 10 | S12: 2.13 | T12: =T11/1.0287 -> 0.75355092 | U12: =S12*T12 -> 1.6050634 | V12: =R12*U12 -> 16.050634 | W12: =R12*(R12+1)*U12 -> 176.55698 | Y12: GMF | Z12: 10 | AA12: 3.05 | AB12: =AB11/1.0305 -> 0.74049143 | AC12: =AA12*AB12 -> 2.2584989 | AD12: =Z12*AC12 -> 22.584989 | AE12: =Z12*(Z12+1)*AC12 -> 248.43488
B13: (1+I/Y)2 | C13: =C12*C12 -> 1.040808 | I13: PFE | J13: 11 | K13: 0.88 | L13: =L12/1.0228 -> 0.78037273 | M13: =K13*L13 -> 0.68672801 | N13: =J13*M13 -> 7.5540081 | O13: =J13*(J13+1)*M13 -> 90.648097 | Q13: JPM | R13: 11 | S13: 2.13 | T13: =T12/1.0287 -> 0.73252738 | U13: =S13*T13 -> 1.5602833 | V13: =R13*U13 -> 17.163117 | W13: =R13*(R13+1)*U13 -> 205.9574 | Y13: GMF | Z13: 11 | AA13: 3.05 | AB13: =AB12/1.0305 -> 0.7185749 | AC13: =AA13*AB13 -> 2.1916534 | AD13: =Z13*AC13 -> 24.108188 | AE13: =Z13*(Z13+1)*AC13 -> 289.29825
B14: Convexity | C14: =(G7)/(E7*C13) -> 18.654969 | I14: PFE | J14: 12 | K14: 0.88 | L14: =L13/1.0228 -> 0.76297686 | M14: =K14*L14 -> 0.67141964 | N14: =J14*M14 -> 8.0570357 | O14: =J14*(J14+1)*M14 -> 104.74146 | Q14: JPM | R14: 12 | S14: 2.13 | T14: =T13/1.0287 -> 0.71209039 | U14: =S14*T14 -> 1.5167525 | V14: =R14*U14 -> 18.20103 | W14: =R14*(R14+1)*U14 -> 236.61339 | Y14: GMF | Z14: 12 | AA14: 3.05 | AB14: =AB13/1.0305 -> 0.69730703 | AC14: =AA14*AB14 -> 2.1267865 | AD14: =Z14*AC14 -> 25.521437 | AE14: =Z14*(Z14+1)*AC14 -> 331.77869
I15: PFE | J15: 13 | K15: 100.88 | L15: =L14/1.0228 -> 0.74596877 | M15: =K15*L15 -> 75.25333 | N15: =J15*M15 -> 978.29329 | O15: =J15*(J15+1)*M15 -> 13696.106 | Q15: JPM | R15: 13 | S15: 2.13 | T15: =T14/1.0287 -> 0.69222357 | U15: =S15*T15 -> 1.4744362 | V15: =R15*U15 -> 19.167671 | W15: =R15*(R15+1)*U15 -> 268.34739 | Y15: GMF | Z15: 13 | AA15: 3.05 | AB15: =AB14/1.0305 -> 0.67666864 | AC15: =AA15*AB15 -> 2.0638394 | AD15: =Z15*AC15 -> 26.829912 | AE15: =Z15*(Z15+1)*AC15 -> 375.61876
L16: Sum | M16: =SUM(M3:M15) -> 84.401591 | N16: =SUM(N3:N15) -> 1035.3023 | O16: =SUM(O3:O15) -> 14216.993 | Q16: JPM | R16: 14 | S16: 2.13 | T16: =T15/1.0287 -> 0.67291102 | U16: =S16*T16 -> 1.4333005 | V16: =R16*U16 -> 20.066207 | W16: =R16*(R16+1)*U16 -> 300.9931 | Y16: GMF | Z16: 14 | AA16: 3.05 | AB16: =AB15/1.0305 -> 0.65664109 | AC16: =AA16*AB16 -> 2.0027553 | AD16: =Z16*AC16 -> 28.038574 | AE16: =Z16*(Z16+1)*AC16 -> 420.57862
Q17: JPM | R17: 15 | S17: 2.13 | T17: =T16/1.0287 -> 0.65413728 | U17: =S17*T17 -> 1.3933124 | V17: =R17*U17 -> 20.899686 | W17: =R17*(R17+1)*U17 -> 334.39498 | Y17: GMF | Z17: 15 | AA17: 3.05 | AB17: =AB16/1.0305 -> 0.6372063 | AC17: =AA17*AB17 -> 1.9434792 | AD17: =Z17*AC17 -> 29.152188 | AE17: =Z17*(Z17+1)*AC17 -> 466.43501
K18: D_Mac | L18: =N16/M16 -> 12.266384 | Q18: JPM | R18: 16 | S18: 2.13 | T18: =T17/1.0287 -> 0.63588732 | U18: =S18*T18 -> 1.35444 | V18: =R18*U18 -> 21.67104 | W18: =R18*(R18+1)*U18 -> 368.40768 | Y18: GMF | Z18: 16 | AA18: 3.05 | AB18: =AB17/1.0305 -> 0.61834672 | AC18: =AA18*AB18 -> 1.8859575 | AD18: =Z18*AC18 -> 30.17532 | AE18: =Z18*(Z18+1)*AC18 -> 512.98044
K19: D_Mod | L19: =L18/L20 -> 11.992945 | Q19: JPM | R19: 17 | S19: 2.13 | T19: =T18/1.0287 -> 0.61814651 | U19: =S19*T19 -> 1.3166521 | V19: =R19*U19 -> 22.383085 | W19: =R19*(R19+1)*U19 -> 402.89553 | Y19: GMF | Z19: 17 | AA19: 3.05 | AB19: =AB18/1.0305 -> 0.60004534 | AC19: =AA19*AB19 -> 1.8301383 | AD19: =Z19*AC19 -> 31.112351 | AE19: =Z19*(Z19+1)*AC19 -> 560.02231
K20: 1+I/Y | L20: 1.0228 | Q20: JPM | R20: 18 | S20: 2.13 | T20: =T19/1.0287 -> 0.60090066 | U20: =S20*T20 -> 1.2799184 | V20: =R20*U20 -> 23.038531 | W20: =R20*(R20+1)*U20 -> 437.7321 | Y20: GMF | Z20: 18 | AA20: 103.05 | AB20: =AB19/1.0305 -> 0.58228563 | AC20: =AA20*AB20 -> 60.004534 | AD20: =Z20*AC20 -> 1080.0816 | AE20: =Z20*(Z20+1)*AC20 -> 20521.551
K21: (1+I/Y)2 | L21: =L20*L20 -> 1.0461198 | Q21: JPM | R21: 19 | S21: 2.13 | T21: =T20/1.0287 -> 0.58413596 | U21: =S21*T21 -> 1.2442096 | V21: =R21*U21 -> 23.639982 | W21: =R21*(R21+1)*U21 -> 472.79965 | AB21: Sum | AC21: =SUM(AC3:AC20) -> 100 | AD21: =SUM(AD3:AD20) -> 1411.3268 | AE21: =SUM(AE3:AE20) -> 24543.647
K22: Convexity | L22: =(O16)/(N16*L21) -> 13.126808 | Q22: JPM | R22: 20 | S22: 2.13 | T22: =T21/1.0287 -> 0.56783898 | U22: =S22*T22 -> 1.209497 | V22: =R22*U22 -> 24.189941 | W22: =R22*(R22+1)*U22 -> 507.98875
Q23: JPM | R23: 21 | S23: 2.13 | T23: =T22/1.0287 -> 0.55199668 | U23: =S23*T23 -> 1.1757529 | V23: =R23*U23 -> 24.690811 | W23: =R23*(R23+1)*U23 -> 543.19785
Q24: JPM | R24: 22 | S24: 2.13 | T24: =T23/1.0287 -> 0.53659636 | U24: =S24*T24 -> 1.1429503 | V24: =R24*U24 -> 25.144906 | W24: =R24*(R24+1)*U24 -> 578.33283 | AA24: D_Mac | AB24: =AD21/AC21 -> 14.113268
Q25: JPM | R25: 23 | S25: 2.13 | T25: =T24/1.0287 -> 0.5216257 | U25: =S25*T25 -> 1.1110627 | V25: =R25*U25 -> 25.554443 | W25: =R25*(R25+1)*U25 -> 613.30664 | AA25: D_Mod | AB25: =AB24/AB26 -> 13.695553
Q26: JPM | R26: 24 | S26: 2.13 | T26: =T25/1.0287 -> 0.50707272 | U26: =S26*T26 -> 1.0800649 | V26: =R26*U26 -> 25.921557 | W26: =R26*(R26+1)*U26 -> 648.03893 | AA26: 1+I/Y | AB26: 1.0305
Q27: JPM | R27: 25 | S27: 2.13 | T27: =T26/1.0287 -> 0.49292575 | U27: =S27*T27 -> 1.0499318 | V27: =R27*U27 -> 26.248296 | W27: =R27*(R27+1)*U27 -> 682.4557 | AA27: (1+I/Y)2 | AB27: =AB26*AB26 -> 1.0619302
Q28: JPM | R28: 26 | S28: 2.13 | T28: =T27/1.0287 -> 0.47917347 | U28: =S28*T28 -> 1.0206395 | V28: =R28*U28 -> 26.536627 | W28: =R28*(R28+1)*U28 -> 716.48892 | AA28: Convexity | AB28: =(AE21)/(AD21*AB27) -> 16.37629
Q29: JPM | R29: 27 | S29: 2.13 | T29: =T28/1.0287 -> 0.46580487 | U29: =S29*T29 -> 0.99216437 | V29: =R29*U29 -> 26.788438 | W29: =R29*(R29+1)*U29 -> 750.07627
Q30: JPM | R30: 28 | S30: 2.13 | T30: =T29/1.0287 -> 0.45280924 | U30: =S30*T30 -> 0.96448369 | V30: =R30*U30 -> 27.005543 | W30: =R30*(R30+1)*U30 -> 783.16076
Q31: JPM | R31: 29 | S31: 2.13 | T31: =T30/1.0287 -> 0.44017619 | U31: =S31*T31 -> 0.93757528 | V31: =R31*U31 -> 27.189683 | W31: =R31*(R31+1)*U31 -> 815.69049
Q32: JPM | R32: 30 | S32: 2.13 | T32: =T31/1.0287 -> 0.42789558 | U32: =S32*T32 -> 0.91141759 | V32: =R32*U32 -> 27.342528 | W32: =R32*(R32+1)*U32 -> 847.61836
Q33: JPM | R33: 31 | S33: 2.13 | T33: =T32/1.0287 -> 0.4159576 | U33: =S33*T33 -> 0.88598969 | V33: =R33*U33 -> 27.46568 | W33: =R33*(R33+1)*U33 -> 878.90177
Q34: JPM | R34: 32 | S34: 2.13 | T34: =T33/1.0287 -> 0.40435268 | U34: =S34*T34 -> 0.86127121 | V34: =R34*U34 -> 27.560679 | W34: =R34*(R34+1)*U34 -> 909.50239
Q35: JPM | R35: 33 | S35: 2.13 | T35: =T34/1.0287 -> 0.39307153 | U35: =S35*T35 -> 0.83724235 | V35: =R35*U35 -> 27.628998 | W35: =R35*(R35+1)*U35 -> 939.38592
Q36: JPM | R36: 34 | S36: 2.13 | T36: =T35/1.0287 -> 0.38210511 | U36: =S36*T36 -> 0.81388388 | V36: =R36*U36 -> 27.672052 | W36: =R36*(R36+1)*U36 -> 968.52182
Q37: JPM | R37: 35 | S37: 2.13 | T37: =T36/1.0287 -> 0.37144465 | U37: =S37*T37 -> 0.7911771 | V37: =R37*U37 -> 27.691199 | W37: =R37*(R37+1)*U37 -> 996.88315
Q38: JPM | R38: 36 | S38: 2.13 | T38: =T37/1.0287 -> 0.36108161 | U38: =S38*T38 -> 0.76910382 | V38: =R38*U38 -> 27.687738 | W38: =R38*(R38+1)*U38 -> 1024.4463
Q39: JPM | R39: 37 | S39: 2.13 | T39: =T38/1.0287 -> 0.35100769 | U39: =S39*T39 -> 0.74764637 | V39: =R39*U39 -> 27.662916 | W39: =R39*(R39+1)*U39 -> 1051.1908
Q40: JPM | R40: 38 | S40: 2.13 | T40: =T39/1.0287 -> 0.34121482 | U40: =S40*T40 -> 0.72678757 | V40: =R40*U40 -> 27.617928 | W40: =R40*(R40+1)*U40 -> 1077.0992
... Q48: JPM | R48: 46 | S48: 102.13 | T48: =T47/1.0287 -> 0.27209338 | U48: =S48*T48 -> 27.788896 | V48: =R48*U48 -> 1278.2892 | W48: =R48*(R48+1)*U48 -> 60079.594
...
